Traceback (most recent call last):
  File "/Users/samson/miniconda3/envs/myenv222/lib/python3.10/site-packages/pandas/core/indexes/base.py", line 3802, in get_loc
    return self._engine.get_loc(casted_key)
  File "pandas/_libs/index.pyx", line 138, in pandas._libs.index.IndexEngine.get_loc
  File "pandas/_libs/index.pyx", line 165, in pandas._libs.index.IndexEngine.get_loc
  File "pandas/_libs/hashtable_class_helper.pxi", line 5745, in pandas._libs.hashtable.PyObjectHashTable.get_item
  File "pandas/_libs/hashtable_class_helper.pxi", line 5753, in pandas._libs.hashtable.PyObjectHashTable.get_item
KeyError: 'condition'

The above exception was the direct cause of the following exception:

Traceback (most recent call last):
  File "/Users/samson/Documents/Final3/wesad2/train-wesad_Ex1b.py", line 36, in <module>
    dataset['condition'] = dataset['condition'].replace(label_mapping)
  File "/Users/samson/miniconda3/envs/myenv222/lib/python3.10/site-packages/pandas/core/frame.py", line 3807, in __getitem__
    indexer = self.columns.get_loc(key)
  File "/Users/samson/miniconda3/envs/myenv222/lib/python3.10/site-packages/pandas/core/indexes/base.py", line 3804, in get_loc
    raise KeyError(key) from err
KeyError: 'condition'
Running Randomized Search for KNN...
Running Randomized Search for RF...
KNN: F1 Score = 0.7731
RF: F1 Score = 0.8349
Training duration: 38.3019 seconds
Running Randomized Search for KNN...
Running Randomized Search for RF...
KNN: F1 Score = 0.7852
RF: F1 Score = 0.8447
Training duration: 46.3627 seconds
